Workbook

Sheet DIARIO 2023
A1: OR | B1: FECHA | C1: Nº Socio | D1: NOMBRE | E1: COG. | F1: CONCEPTO | G1: Amplia concepto | H1: Importe | I1: Matri | J1: Transf.
A2: 1 | B2: 44935 | C2: 2003 | D2: CARMEN SORIANO PARRA | E2: 1 | F2: =IFERROR(LOOKUP(E2,CODIGOS!A:A,CODIGOS!B:B)," ") -> CUOTA SOCIO | H2: 20 | I2: SI
A3: 2 | B3: 44935 | C3: 1930 | D3: MANUEL CORRALES CARRETERO | E3: 1 | F3: =IFERROR(LOOKUP(E3,CODIGOS!A:A,CODIGOS!B:B)," ") -> CUOTA SOCIO | H3: 20 | I3: SI
A4: 3 | B4: 44935 | C4: 2004 | D4: FRANCIS MANGAS MACIAS | E4: 1 | F4: =IFERROR(LOOKUP(E4,CODIGOS!A:A,CODIGOS!B:B)," ") -> CUOTA SOCIO | H4: 20 | I4: SI
A5: 4 | B5: 44935 | C5: 2324 | D5: GRACIAS FIESTA MORILLA | E5: 1 | F5: =IFERROR(LOOKUP(E5,CODIGOS!A:A,CODIGOS!B:B)," ") -> CUOTA SOCIO | H5: 20 | I5: SI
A6: 5 | B6: 44935 | C6: 2392 | D6: ANA SANCHEZ GONZALEZ | E6: 1 | F6: =IFERROR(LOOKUP(E6,CODIGOS!A:A,CODIGOS!B:B)," ") -> CUOTA SOCIO | H6: 20 | I6: SI
A7: 6 | B7: 44935 | C7: 2570 | D7: JOSE ENRIQUE GARCIA FERNANDEZ | E7: 1 | F7: =IFERROR(LOOKUP(E7,CODIGOS!A:A,CODIGOS!B:B)," ") -> CUOTA SOCIO | H7: 20 | I7: SI
A8: 7 | B8: 44935 | C8: 2571 | D8: ENCARNACION CHINCHILLA FERNANDEZ | E8: 1 | F8: =IFERROR(LOOKUP(E8,CODIGOS!A:A,CODIGOS!B:B)," ") -> CUOTA SOCIO | H8: 20 | I8: SI
A9: 8 | B9: 44935 | C9: 1680 | D9: LOLI CONTRERAS GONZALEZ | E9: 1 | F9: =IFERROR(LOOKUP(E9,CODIGOS!A:A,CODIGOS!B:B)," ") -> CUOTA SOCIO | H9: 20 | I9: SI
A10: 9 | B10: 44935 | C10: 2105 | D10: ISABEL NAVARRO DE OÑA | E10: 1 | F10: =IFERROR(LOOKUP(E10,CODIGOS!A:A,CODIGOS!B:B)," ") -> CUOTA SOCIO | H10: 20 | I10: NO
A11: 10 | B11: 44935 | C11: 575 | D11: TERESA BAUTISTA MENDEZ | E11: 1 | F11: =IFERROR(LOOKUP(E11,CODIGOS!A:A,CODIGOS!B:B)," ") -> CUOTA SOCIO | H11: 20 | I11: NO
A12: 11 | B12: 44935 | C12: 410 | D12: LUCIA LOPEZ BIEZMA | E12: 1 | F12: =IFERROR(LOOKUP(E12,CODIGOS!A:A,CODIGOS!B:B)," ") -> CUOTA SOCIO | H12: 20 | I12: NO
A13: 12 | B13: 44935 | C13: A/410 | D13: EMILIA HITA ROMERO | E13: 1 | F13: =IFERROR(LOOKUP(E13,CODIGOS!A:A,CODIGOS!B:B)," ") -> CUOTA SOCIO | H13: 30 | I13: NO
A14: 13 | B14: 44935 | C14: 2555 | D14: ANTONIO LARA ARCOS | E14: 1 | F14: =IFERROR(LOOKUP(E14,CODIGOS!A:A,CODIGOS!B:B)," ") -> CUOTA SOCIO | H14: 20 | I14: SI
A15: 14 | B15: 44935 | C15: 1982 | D15: Mª LUISA GARZON VALDEARENAS | E15: 1 | F15: =IFERROR(LOOKUP(E15,CODIGOS!A:A,CODIGOS!B:B)," ") -> CUOTA SOCIO | H15: 20 | I15: SI
A16: 15 | B16: 44935 | C16: A/2555 | D16: Mª AGEDA MARTIN RUEDA | E16: 1 | F16: =IFERROR(LOOKUP(E16,CODIGOS!A:A,CODIGOS!B:B)," ") -> CUOTA SOCIO | H16: 30 | I16: NO
A17: 16 | B17: 44935 | C17: 2489 | D17: PILAR TORRES PEREA | E17: 1 | F17: =IFERROR(LOOKUP(E17,CODIGOS!A:A,CODIGOS!B:B)," ") -> CUOTA SOCIO | H17: 20 | I17: SI
A18: 17 | B18: 44936 | C18: 2131 | D18: ANTONIO SANCHEZ GARCIA | E18: 1 | F18: =IFERROR(LOOKUP(E18,CODIGOS!A:A,CODIGOS!B:B)," ") -> CUOTA SOCIO | H18: 20 | I18: SI
A19: 18 | B19: 44936 | C19: A/2131 | D19: Mª ANGUSTIAS MOLINA QUESADA | E19: 1 | F19: =IFERROR(LOOKUP(E19,CODIGOS!A:A,CODIGOS!B:B)," ") -> CUOTA SOCIO | H19: 30 | I19: NO
A20: 19 | B20: 44936 | C20: 2559 | D20: Mª JOSE DIAZ CARRILLO | E20: 1 | F20: =IFERROR(LOOKUP(E20,CODIGOS!A:A,CODIGOS!B:B)," ") -> CUOTA SOCIO | H20: 20 | I20: SI
A21: 20 | B21: 44936 | C21: 2588 | D21: INMACULADA DIAZ FLORES | E21: 2 | F21: =IFERROR(LOOKUP(E21,CODIGOS!A:A,CODIGOS!B:B)," ") -> CUOTA NUEVO SOCIO | H21: 5 | I21: SI
A22: 21 | B22: 44936 | C22: 2314 | D22: Eloy de Haro Muñoz | E22: 2 | F22: =IFERROR(LOOKUP(E22,CODIGOS!A:A,CODIGOS!B:B)," ") -> CUOTA NUEVO SOCIO | H22: 5
A23: 22 | B23: 44936 | C23: 2315 | D23: Mª Consolación Romero González | E23: 2 | F23: =IFERROR(LOOKUP(E23,CODIGOS!A:A,CODIGOS!B:B)," ") -> CUOTA NUEVO SOCIO | H23: 5
A24: 23 | B24: 44936 | C24: 2471 | D24: Mª Jesús Sánchez Pérez | E24: 1 | F24: =IFERROR(LOOKUP(E24,CODIGOS!A:A,CODIGOS!B:B)," ") -> CUOTA SOCIO | H24: 20
A25: 24 | B25: 44937 | C25: 2492 | D25: INMACULADA CABALLERO BUENO | E25: 2 | F25: =IFERROR(LOOKUP(E25,CODIGOS!A:A,CODIGOS!B:B)," ") -> CUOTA NUEVO SOCIO | H25: 5
A26: 25 | B26: 44937 | C26: 2414 | D26: FRANCISCA GARCIA GOMEZ | E26: 1 | F26: =IFERROR(LOOKUP(E26,CODIGOS!A:A,CODIGOS!B:B)," ") -> CUOTA SOCIO | H26: 20 | I26: SI
A27: 26 | B27: 44937 | C27: 2456 | D27: SEBASTIAN TELLEZ SANCHEZ | E27: 1 | F27: =IFERROR(LOOKUP(E27,CODIGOS!A:A,CODIGOS!B:B)," ") -> CUOTA SOCIO | H27: 20 | I27: NO
A28: 27 | B28: 44937 | C28: 2557 | D28: Mª JOSE HERNANDEZ CASADO | E28: 55 | F28: =IFERROR(LOOKUP(E28,CODIGOS!A:A,CODIGOS!B:B)," ") -> 0 | H28: 25 | I28: SI
A29: 28 | B29: 44937 | C29: 2706 | D29: ANTONIO CAMERO CIFUENTES | E29: 2 | F29: =IFERROR(LOOKUP(E29,CODIGOS!A:A,CODIGOS!B:B)," ") -> CUOTA NUEVO SOCIO | H29: 5
A30: 29 | B30: 44942 | C30: 1823 | D30: INMA CAÑAVATE | E30: 1 | F30: =IFERROR(LOOKUP(E30,CODIGOS!A:A,CODIGOS!B:B)," ") -> CUOTA SOCIO | H30: 20 | I30: SI
A31: 30 | B31: 44942 | C31: 1433 | D31: JOSE RODRIGUEZ SANCHEZ | E31: 2 | F31: =IFERROR(LOOKUP(E31,CODIGOS!A:A,CODIGOS!B:B)," ") -> CUOTA NUEVO SOCIO | H31: 15 | I31: 3
A32: 31 | B32: 44943 | C32: 2679 | D32: ENCARNITA MORENO ZURITA | E32: 3 | F32: =IFERROR(LOOKUP(E32,CODIGOS!A:A,CODIGOS!B:B)," ") -> 0 | H32: 5
A33: 32 | B33: 44943 | C33: A/1920 | D33: Josefa Sancho Lledó | E33: 1 | F33: =IFERROR(LOOKUP(E33,CODIGOS!A:A,CODIGOS!B:B)," ") -> CUOTA SOCIO | H33: 20
A34: 33 | B34: 44944 | C34: 1920 | D34: PEPE HERAS | E34: 4 | F34: =IFERROR(LOOKUP(E34,CODIGOS!A:A,CODIGOS!B:B)," ") -> DEVOLUCION | H34: 15 | I34: SI
A35: 34 | B35: 44944 | C35: 2563 | D35: VICTORIANO MARTIN | E35: 4 | F35: =IFERROR(LOOKUP(E35,CODIGOS!A:A,CODIGOS!B:B)," ") -> DEVOLUCION | H35: 15 | I35: SI
A36: 35 | B36: 44944 | C36: A/1920 | D36: PEPA SÁNCHO | E36: 4 | F36: =IFERROR(LOOKUP(E36,CODIGOS!A:A,CODIGOS!B:B)," ") -> DEVOLUCION | H36: 15 | I36: NO
A37: 36 | B37: 44944 | C37: 269 | D37: JUAN FRANCISCO ACEÑA CABALLERO | E37: 4 | F37: =IFERROR(LOOKUP(E37,CODIGOS!A:A,CODIGOS!B:B)," ") -> DEVOLUCION | H37: 15 | I37: SI
A38: 37 | B38: 44944 | C38: A/269 | D38: Mª ÁNGELES PALOMINO PALOMINO | E38: 5 | F38: =IFERROR(LOOKUP(E38,CODIGOS!A:A,CODIGOS!B:B)," ") -> 0 | H38: 20 | I38: NO
A39: 38 | B39: 44944 | C39: 2632 | D39: ANTONIO BAENA CORTÉS | E39: 5 | F39: =IFERROR(LOOKUP(E39,CODIGOS!A:A,CODIGOS!B:B)," ") -> 0 | H39: 15 | I39: SI
A40: 39 | B40: 44944 | C40: 2553 | D40: JOSÉ J. PÉREZ BLANCO | E40: 5 | F40: =IFERROR(LOOKUP(E40,CODIGOS!A:A,CODIGOS!B:B)," ") -> 0 | H40: 15 | I40: SI
...

Sheet DIARIO 2026
A1: OR | B1: FECHA | C1: Nº Socio | D1: NOMBRE | E1: COG. | F1: CONCEPTO | H1: Importe | I1: Matriculado | J1: SOCIO | K1: Transf.
A2: 1 | D2: NO ESCRIBIR | F2: =IFERROR(LOOKUP(E2,CODIGOS!A:A,CODIGOS!B:B)," ") | I2: =IFERROR(LOOKUP(C2,SOCIO!A:A,SOCIO!D:D)," ")
A3: =IF(B3<>0,A2+1," ") -> 2 | B3: 46034 | C3: 2823 | D3: CORRAL SOLA, MARÍA | E3: 11 | F3: =IFERROR(LOOKUP(E3,CODIGOS!A:A,CODIGOS!B:B)," ") -> OLLA SAN ANTÓN | H3: =IF(I3="SI",IFERROR(LOOKUP(E3,CODIGOS!A:A,CODIGOS!C:C)," "),IFERROR(LOOKUP(E3,CODIGOS!A:A,CODIGOS!D:D),"")) -> 25 | I3: =IFERROR(LOOKUP(C3,SOCIO!A:A,SOCIO!D:D)," ") -> SI | J3: =IFERROR(LOOKUP(D3,SOCIO!B:B,SOCIO!C:C)," ") -> SI
A4: =IF(B4<>0,A3+1," ") -> 3 | B4: 46034 | C4: 2823 | D4: CORRAL SOLA, MARÍA | E4: 12 | F4: =IFERROR(LOOKUP(E4,CODIGOS!A:A,CODIGOS!B:B)," ") -> EXPOSICIÓN CATEDRAL | H4: =IF(J4="SI",IFERROR(LOOKUP(E4,CODIGOS!A:A,CODIGOS!C:C)," "),IFERROR(LOOKUP(E4,CODIGOS!A:A,CODIGOS!D:D),"")) -> 3 | I4: NO | J4: =IFERROR(LOOKUP(D4,SOCIO!B:B,SOCIO!C:C)," ") -> SI
A5: =IF(B5<>0,A4+1," ") -> 4 | B5: 46034 | C5: A/1920 | D5: SANCHO LLEDÓ, PEPA | E5: 11 | F5: =IFERROR(LOOKUP(E5,CODIGOS!A:A,CODIGOS!B:B)," ") -> OLLA SAN ANTÓN | H5: =IF(J5="SI",IFERROR(LOOKUP(E5,CODIGOS!A:A,CODIGOS!C:C)," "),IFERROR(LOOKUP(E5,CODIGOS!A:A,CODIGOS!D:D),"")) -> 25 | I5: =IFERROR(LOOKUP(C5,SOCIO!A:A,SOCIO!D:D)," ") | J5: =IFERROR(LOOKUP(D5,SOCIO!B:B,SOCIO!C:C)," ") -> SI
A6: =IF(B6<>0,A5+1," ") -> 5 | B6: 46034 | C6: A/2498 | D6: ABAD ORTEGA, MARIA DEL MARº | E6: 11 | F6: =IFERROR(LOOKUP(E6,CODIGOS!A:A,CODIGOS!B:B)," ") -> OLLA SAN ANTÓN | H6: =IF(J6="SI",IFERROR(LOOKUP(E6,CODIGOS!A:A,CODIGOS!C:C)," "),IFERROR(LOOKUP(E6,CODIGOS!A:A,CODIGOS!D:D),"")) -> 30 | I6: =IFERROR(LOOKUP(C6,SOCIO!A:A,SOCIO!D:D)," ") | J6: =IFERROR(LOOKUP(D6,SOCIO!B:B,SOCIO!C:C)," ")
A7: =IF(B7<>0,A6+1," ") -> 6 | B7: 46034 | C7: 1920 | D7: HERAS JIMENEZ, JOSE FRANCISCO | E7: 12 | F7: =IFERROR(LOOKUP(E7,CODIGOS!A:A,CODIGOS!B:B)," ") -> EXPOSICIÓN CATEDRAL | H7: =IF(J7="SI",IFERROR(LOOKUP(E7,CODIGOS!A:A,CODIGOS!C:C)," "),IFERROR(LOOKUP(E7,CODIGOS!A:A,CODIGOS!D:D),"")) -> 3 | I7: =IFERROR(LOOKUP(C7,SOCIO!A:A,SOCIO!D:D)," ") -> SI | J7: =IFERROR(LOOKUP(D7,SOCIO!B:B,SOCIO!C:C)," ") -> SI
A8: =IF(B8<>0,A7+1," ") -> 7 | B8: 46034 | C8: A/1920 | D8: SANCHO LLEDÓ, PEPA | E8: 12 | F8: =IFERROR(LOOKUP(E8,CODIGOS!A:A,CODIGOS!B:B)," ") -> EXPOSICIÓN CATEDRAL | H8: =IF(J8="SI",IFERROR(LOOKUP(E8,CODIGOS!A:A,CODIGOS!C:C)," "),IFERROR(LOOKUP(E8,CODIGOS!A:A,CODIGOS!D:D),"")) -> 3 | I8: =IFERROR(LOOKUP(C8,SOCIO!A:A,SOCIO!D:D)," ") | J8: =IFERROR(LOOKUP(D8,SOCIO!B:B,SOCIO!C:C)," ") -> SI
A9: =IF(B9<>0,A8+1," ") -> 8 | B9: 46034 | C9: 1920 | D9: HERAS JIMENEZ, JOSE FRANCISCO | E9: 10 | F9: =IFERROR(LOOKUP(E9,CODIGOS!A:A,CODIGOS!B:B)," ") -> ÓRGIVA | H9: =IF(J9="SI",IFERROR(LOOKUP(E9,CODIGOS!A:A,CODIGOS!C:C)," "),IFERROR(LOOKUP(E9,CODIGOS!A:A,CODIGOS!D:D),"")) -> 22 | I9: =IFERROR(LOOKUP(C9,SOCIO!A:A,SOCIO!D:D)," ") -> SI | J9: =IFERROR(LOOKUP(D9,SOCIO!B:B,SOCIO!C:C)," ") -> SI
A10: =IF(B10<>0,A9+1," ") -> 9 | B10: 46034 | C10: A/1920 | D10: SANCHO LLEDÓ, PEPA | E10: 10 | F10: =IFERROR(LOOKUP(E10,CODIGOS!A:A,CODIGOS!B:B)," ") -> ÓRGIVA | H10: =IF(J10="SI",IFERROR(LOOKUP(E10,CODIGOS!A:A,CODIGOS!C:C)," "),IFERROR(LOOKUP(E10,CODIGOS!A:A,CODIGOS!D:D),"")) -> 22 | I10: =IFERROR(LOOKUP(C10,SOCIO!A:A,SOCIO!D:D)," ") | J10: =IFERROR(LOOKUP(D10,SOCIO!B:B,SOCIO!C:C)," ") -> SI
A11: =IF(B11<>0,A10+1," ") -> 10 | B11: 46034 | C11: 2673 | D11: VALDEARENAS, MANUEL | E11: 11 | F11: =IFERROR(LOOKUP(E11,CODIGOS!A:A,CODIGOS!B:B)," ") -> OLLA SAN ANTÓN | H11: =IF(J11="SI",IFERROR(LOOKUP(E11,CODIGOS!A:A,CODIGOS!C:C)," "),IFERROR(LOOKUP(E11,CODIGOS!A:A,CODIGOS!D:D),"")) -> 25 | I11: =IFERROR(LOOKUP(C11,SOCIO!A:A,SOCIO!D:D)," ") -> SI | J11: =IFERROR(LOOKUP(D11,SOCIO!B:B,SOCIO!C:C)," ") -> SI
A12: =IF(B12<>0,A11+1," ") -> 11 | B12: 46034 | C12: 2900 | D12: MURILLO, HELMER | E12: 11 | F12: =IFERROR(LOOKUP(E12,CODIGOS!A:A,CODIGOS!B:B)," ") -> OLLA SAN ANTÓN | H12: =IF(J12="SI",IFERROR(LOOKUP(E12,CODIGOS!A:A,CODIGOS!C:C)," "),IFERROR(LOOKUP(E12,CODIGOS!A:A,CODIGOS!D:D),"")) -> 25 | I12: =IFERROR(LOOKUP(C12,SOCIO!A:A,SOCIO!D:D)," ") -> SI | J12: =IFERROR(LOOKUP(D12,SOCIO!B:B,SOCIO!C:C)," ") -> SI
A13: =IF(B13<>0,A12+1," ") -> 12 | B13: 46034 | C13: A/2900 | D13: MURILLO, FLOR | E13: 11 | F13: =IFERROR(LOOKUP(E13,CODIGOS!A:A,CODIGOS!B:B)," ") -> OLLA SAN ANTÓN | H13: 30 | I13: =IFERROR(LOOKUP(C13,SOCIO!A:A,SOCIO!D:D)," ") | J13: =IFERROR(LOOKUP(D13,SOCIO!B:B,SOCIO!C:C)," ") -> SI
A14: =IF(B14<>0,A13+1," ") -> 13 | B14: 46034 | C14: 2134 | D14: ROLDAN, MARIA | E14: 11 | F14: =IFERROR(LOOKUP(E14,CODIGOS!A:A,CODIGOS!B:B)," ") -> OLLA SAN ANTÓN | H14: =IF(J14="SI",IFERROR(LOOKUP(E14,CODIGOS!A:A,CODIGOS!C:C)," "),IFERROR(LOOKUP(E14,CODIGOS!A:A,CODIGOS!D:D),"")) -> 25 | I14: =IFERROR(LOOKUP(C14,SOCIO!A:A,SOCIO!D:D)," ") -> NO | J14: =IFERROR(LOOKUP(D14,SOCIO!B:B,SOCIO!C:C)," ") -> SI
A15: =IF(B15<>0,A14+1," ") -> 14 | B15: 46034 | C15: 2961 | D15: ESPINOSA FREIRE, ADELINA | E15: 11 | F15: =IFERROR(LOOKUP(E15,CODIGOS!A:A,CODIGOS!B:B)," ") -> OLLA SAN ANTÓN | H15: =IF(J15="SI",IFERROR(LOOKUP(E15,CODIGOS!A:A,CODIGOS!C:C)," "),IFERROR(LOOKUP(E15,CODIGOS!A:A,CODIGOS!D:D),"")) -> 25 | I15: =IFERROR(LOOKUP(C15,SOCIO!A:A,SOCIO!D:D)," ") -> SI | J15: =IFERROR(LOOKUP(D15,SOCIO!B:B,SOCIO!C:C)," ") -> SI
A16: =IF(B16<>0,A15+1," ") -> 15 | B16: 46034 | C16: 3152 | D16: GONZALEZ CASTELLON, RITA BELEN | E16: 2 | F16: =IFERROR(LOOKUP(E16,CODIGOS!A:A,CODIGOS!B:B)," ") -> CUOTA NUEVO SOCIO | H16: =IF(J16="SI",IFERROR(LOOKUP(E16,CODIGOS!A:A,CODIGOS!C:C)," "),IFERROR(LOOKUP(E16,CODIGOS!A:A,CODIGOS!D:D),"")) -> 30 | I16: =IFERROR(LOOKUP(C16,SOCIO!A:A,SOCIO!D:D)," ") -> SI | J16: =IFERROR(LOOKUP(D16,SOCIO!B:B,SOCIO!C:C)," ") -> SI
A17: =IF(B17<>0,A16+1," ") -> 16 | B17: 46034 | C17: 3153 | D17: PEREZ SERRANO, FRANCISCA | E17: 2 | F17: =IFERROR(LOOKUP(E17,CODIGOS!A:A,CODIGOS!B:B)," ") -> CUOTA NUEVO SOCIO | H17: =IF(J17="SI",IFERROR(LOOKUP(E17,CODIGOS!A:A,CODIGOS!C:C)," "),IFERROR(LOOKUP(E17,CODIGOS!A:A,CODIGOS!D:D),"")) -> 30 | I17: =IFERROR(LOOKUP(C17,SOCIO!A:A,SOCIO!D:D)," ") -> SI | J17: =IFERROR(LOOKUP(D17,SOCIO!B:B,SOCIO!C:C)," ") -> SI
A18: =IF(B18<>0,A17+1," ") -> 17 | B18: 46035 | C18: 2900 | D18: MURILLO, HELMER | E18: 10 | F18: =IFERROR(LOOKUP(E18,CODIGOS!A:A,CODIGOS!B:B)," ") -> ÓRGIVA | H18: =IF(J18="SI",IFERROR(LOOKUP(E18,CODIGOS!A:A,CODIGOS!C:C)," "),IFERROR(LOOKUP(E18,CODIGOS!A:A,CODIGOS!D:D),"")) -> 22 | I18: =IFERROR(LOOKUP(C18,SOCIO!A:A,SOCIO!D:D)," ") -> SI | J18: =IFERROR(LOOKUP(D18,SOCIO!B:B,SOCIO!C:C)," ") -> SI
A19: =IF(B19<>0,A18+1," ") -> 18 | B19: 46035 | C19: A/2900 | D19: MURILLO, FLOR | E19: 10 | F19: =IFERROR(LOOKUP(E19,CODIGOS!A:A,CODIGOS!B:B)," ") -> ÓRGIVA | H19: 27 | I19: =IFERROR(LOOKUP(C19,SOCIO!A:A,SOCIO!D:D)," ") | J19: =IFERROR(LOOKUP(D19,SOCIO!B:B,SOCIO!C:C)," ") -> SI
A20: =IF(B20<>0,A19+1," ") -> 19 | B20: 46035 | C20: 2109 | D20: BELTRAN CABRERA, MARILUZ | E20: 10 | F20: =IFERROR(LOOKUP(E20,CODIGOS!A:A,CODIGOS!B:B)," ") -> ÓRGIVA | H20: =IF(J20="SI",IFERROR(LOOKUP(E20,CODIGOS!A:A,CODIGOS!C:C)," "),IFERROR(LOOKUP(E20,CODIGOS!A:A,CODIGOS!D:D),"")) -> 22 | I20: =IFERROR(LOOKUP(C20,SOCIO!A:A,SOCIO!D:D)," ") -> SI | J20: =IFERROR(LOOKUP(D20,SOCIO!B:B,SOCIO!C:C)," ") -> SI
A21: =IF(B21<>0,A20+1," ") -> 20 | B21: 46035 | C21: 2108 | D21: BLASCO AZAUSTRE, MARGARITA | E21: 10 | F21: =IFERROR(LOOKUP(E21,CODIGOS!A:A,CODIGOS!B:B)," ") -> ÓRGIVA | H21: =IF(J21="SI",IFERROR(LOOKUP(E21,CODIGOS!A:A,CODIGOS!C:C)," "),IFERROR(LOOKUP(E21,CODIGOS!A:A,CODIGOS!D:D),"")) -> 22 | I21: =IFERROR(LOOKUP(C21,SOCIO!A:A,SOCIO!D:D)," ") -> SI | J21: =IFERROR(LOOKUP(D21,SOCIO!B:B,SOCIO!C:C)," ") -> SI
A22: =IF(B22<>0,A21+1," ") -> 21 | B22: 46035 | C22: 2109 | D22: BELTRAN CABRERA, MARILUZ | E22: 11 | F22: =IFERROR(LOOKUP(E22,CODIGOS!A:A,CODIGOS!B:B)," ") -> OLLA SAN ANTÓN | H22: =IF(J22="SI",IFERROR(LOOKUP(E22,CODIGOS!A:A,CODIGOS!C:C)," "),IFERROR(LOOKUP(E22,CODIGOS!A:A,CODIGOS!D:D),"")) -> 25 | I22: =IFERROR(LOOKUP(C22,SOCIO!A:A,SOCIO!D:D)," ") -> SI | J22: =IFERROR(LOOKUP(D22,SOCIO!B:B,SOCIO!C:C)," ") -> SI
A23: =IF(B23<>0,A22+1," ") -> 22 | B23: 46035 | C23: 2108 | D23: BLASCO AZAUSTRE, MARGARITA | E23: 11 | F23: =IFERROR(LOOKUP(E23,CODIGOS!A:A,CODIGOS!B:B)," ") -> OLLA SAN ANTÓN | H23: =IF(J23="SI",IFERROR(LOOKUP(E23,CODIGOS!A:A,CODIGOS!C:C)," "),IFERROR(LOOKUP(E23,CODIGOS!A:A,CODIGOS!D:D),"")) -> 25 | I23: =IFERROR(LOOKUP(C23,SOCIO!A:A,SOCIO!D:D)," ") -> SI | J23: =IFERROR(LOOKUP(D23,SOCIO!B:B,SOCIO!C:C)," ") -> SI
A24: =IF(B24<>0,A23+1," ") -> 23 | B24: 46035 | C24: 2900 | D24: MURILLO, HELMER | E24: 12 | F24: =IFERROR(LOOKUP(E24,CODIGOS!A:A,CODIGOS!B:B)," ") -> EXPOSICIÓN CATEDRAL | H24: =IF(J24="SI",IFERROR(LOOKUP(E24,CODIGOS!A:A,CODIGOS!C:C)," "),IFERROR(LOOKUP(E24,CODIGOS!A:A,CODIGOS!D:D),"")) -> 3 | I24: =IFERROR(LOOKUP(C24,SOCIO!A:A,SOCIO!D:D)," ") -> SI | J24: =IFERROR(LOOKUP(D24,SOCIO!B:B,SOCIO!C:C)," ") -> SI
A25: =IF(B25<>0,A24+1," ") -> 24 | B25: 46035 | C25: =IFERROR(LOOKUP(D25,SOCIO!B:B,SOCIO!A:A),"") -> 2709 | D25: MATEOS DELGADO,MERCEDES | E25: 10 | F25: =IFERROR(LOOKUP(E25,CODIGOS!A:A,CODIGOS!B:B)," ") -> ÓRGIVA | H25: =IF(J25="SI",IFERROR(LOOKUP(E25,CODIGOS!A:A,CODIGOS!C:C)," "),IFERROR(LOOKUP(E25,CODIGOS!A:A,CODIGOS!D:D),"")) -> 22 | I25: =IFERROR(LOOKUP(C25,SOCIO!A:A,SOCIO!D:D)," ") -> SI | J25: =IFERROR(LOOKUP(D25,SOCIO!B:B,SOCIO!C:C)," ") -> SI
A26: =IF(B26<>0,A25+1," ") -> 25 | B26: 46035 | C26: 2710 | D26: TORICES VILCHEZ, ANTONIO | E26: 10 | F26: =IFERROR(LOOKUP(E26,CODIGOS!A:A,CODIGOS!B:B)," ") -> ÓRGIVA | H26: =IF(J26="SI",IFERROR(LOOKUP(E26,CODIGOS!A:A,CODIGOS!C:C)," "),IFERROR(LOOKUP(E26,CODIGOS!A:A,CODIGOS!D:D),"")) -> 22 | I26: =IFERROR(LOOKUP(C26,SOCIO!A:A,SOCIO!D:D)," ") -> SI | J26: =IFERROR(LOOKUP(D26,SOCIO!B:B,SOCIO!C:C)," ") -> SI
A27: =IF(B27<>0,A26+1," ") -> 26 | B27: 46035 | C27: 2612 | D27: GALLEGO LORCA, ANTONIO | E27: 10 | F27: =IFERROR(LOOKUP(E27,CODIGOS!A:A,CODIGOS!B:B)," ") -> ÓRGIVA | H27: =IF(J27="SI",IFERROR(LOOKUP(E27,CODIGOS!A:A,CODIGOS!C:C)," "),IFERROR(LOOKUP(E27,CODIGOS!A:A,CODIGOS!D:D),"")) -> 22 | I27: =IFERROR(LOOKUP(C27,SOCIO!A:A,SOCIO!D:D)," ") -> NO | J27: =IFERROR(LOOKUP(D27,SOCIO!B:B,SOCIO!C:C)," ") -> SI
A28: =IF(B28<>0,A27+1," ") -> 27 | B28: 46035 | C28: 2527 | D28: RAMIREZ GARCIA, JOSE ANTONIO | E28: 10 | F28: =IFERROR(LOOKUP(E28,CODIGOS!A:A,CODIGOS!B:B)," ") -> ÓRGIVA | H28: =IF(J28="SI",IFERROR(LOOKUP(E28,CODIGOS!A:A,CODIGOS!C:C)," "),IFERROR(LOOKUP(E28,CODIGOS!A:A,CODIGOS!D:D),"")) -> 22 | I28: =IFERROR(LOOKUP(C28,SOCIO!A:A,SOCIO!D:D)," ") -> NO | J28: =IFERROR(LOOKUP(D28,SOCIO!B:B,SOCIO!C:C)," ") -> SI
A29: =IF(B29<>0,A28+1," ") -> 28 | B29: 46035 | C29: 2553 | D29: PREZ BLANCO, JOSE JOAQUIN | E29: 10 | F29: =IFERROR(LOOKUP(E29,CODIGOS!A:A,CODIGOS!B:B)," ") -> ÓRGIVA | H29: =IF(J29="SI",IFERROR(LOOKUP(E29,CODIGOS!A:A,CODIGOS!C:C)," "),IFERROR(LOOKUP(E29,CODIGOS!A:A,CODIGOS!D:D),"")) -> 22 | I29: =IFERROR(LOOKUP(C29,SOCIO!A:A,SOCIO!D:D)," ") -> NO | J29: =IFERROR(LOOKUP(D29,SOCIO!B:B,SOCIO!C:C)," ") -> SI
A30: =IF(B30<>0,A29+1," ") -> 29 | B30: 46035 | C30: 2817 | D30: GUERRERO BARQUERO, JOSE ANTONIO | E30: 10 | F30: =IFERROR(LOOKUP(E30,CODIGOS!A:A,CODIGOS!B:B)," ") -> ÓRGIVA | H30: =IF(J30="SI",IFERROR(LOOKUP(E30,CODIGOS!A:A,CODIGOS!C:C)," "),IFERROR(LOOKUP(E30,CODIGOS!A:A,CODIGOS!D:D),"")) -> 22 | I30: =IFERROR(LOOKUP(C30,SOCIO!A:A,SOCIO!D:D)," ") -> SI | J30: =IFERROR(LOOKUP(D30,SOCIO!B:B,SOCIO!C:C)," ") -> SI
A31: =IF(B31<>0,A30+1," ") -> 30 | B31: 46035 | C31: 2755 | D31: MORALES GONZALEZ, ISABEL | E31: 10 | F31: =IFERROR(LOOKUP(E31,CODIGOS!A:A,CODIGOS!B:B)," ") -> ÓRGIVA | H31: =IF(J31="SI",IFERROR(LOOKUP(E31,CODIGOS!A:A,CODIGOS!C:C)," "),IFERROR(LOOKUP(E31,CODIGOS!A:A,CODIGOS!D:D),"")) -> 22 | I31: =IFERROR(LOOKUP(C31,SOCIO!A:A,SOCIO!D:D)," ") -> SI | J31: =IFERROR(LOOKUP(D31,SOCIO!B:B,SOCIO!C:C)," ") -> SI
A32: =IF(B32<>0,A31+1," ") -> 31 | B32: 46035 | C32: 2756 | D32: JIMENEZ AGUILAR, ANTONIO | E32: 10 | F32: =IFERROR(LOOKUP(E32,CODIGOS!A:A,CODIGOS!B:B)," ") -> ÓRGIVA | H32: =IF(J32="SI",IFERROR(LOOKUP(E32,CODIGOS!A:A,CODIGOS!C:C)," "),IFERROR(LOOKUP(E32,CODIGOS!A:A,CODIGOS!D:D),"")) -> 22 | I32: =IFERROR(LOOKUP(C32,SOCIO!A:A,SOCIO!D:D)," ") -> SI | J32: =IFERROR(LOOKUP(D32,SOCIO!B:B,SOCIO!C:C)," ") -> SI
A33: =IF(B33<>0,A32+1," ") -> 32 | B33: 46035 | C33: 2764 | D33: JIMENEZ RAMOS, JUAN | E33: 10 | F33: =IFERROR(LOOKUP(E33,CODIGOS!A:A,CODIGOS!B:B)," ") -> ÓRGIVA | H33: =IF(J33="SI",IFERROR(LOOKUP(E33,CODIGOS!A:A,CODIGOS!C:C)," "),IFERROR(LOOKUP(E33,CODIGOS!A:A,CODIGOS!D:D),"")) -> 22 | I33: =IFERROR(LOOKUP(C33,SOCIO!A:A,SOCIO!D:D)," ") -> SI | J33: =IFERROR(LOOKUP(D33,SOCIO!B:B,SOCIO!C:C)," ") -> SI
A34: =IF(B34<>0,A33+1," ") -> 33 | B34: 46035 | C34: 2343 | D34: MONTORO GARCIA, SOFIA | E34: 1 | F34: =IFERROR(LOOKUP(E34,CODIGOS!A:A,CODIGOS!B:B)," ") -> CUOTA SOCIO | H34: 30 | I34: =IFERROR(LOOKUP(C34,SOCIO!A:A,SOCIO!D:D)," ") -> NO | J34: NO
A35: =IF(B35<>0,A34+1," ") -> 34 | B35: 46035 | C35: 1923 | D35: CAÑAVATE FERNANDEZ, INMA | E35: 11 | F35: =IFERROR(LOOKUP(E35,CODIGOS!A:A,CODIGOS!B:B)," ") -> OLLA SAN ANTÓN | H35: =IF(J35="SI",IFERROR(LOOKUP(E35,CODIGOS!A:A,CODIGOS!C:C)," "),IFERROR(LOOKUP(E35,CODIGOS!A:A,CODIGOS!D:D),"")) -> 25 | I35: =IFERROR(LOOKUP(C35,SOCIO!A:A,SOCIO!D:D)," ") -> SI | J35: =IFERROR(LOOKUP(D35,SOCIO!B:B,SOCIO!C:C)," ") -> SI
A36: =IF(B36<>0,A35+1," ") -> 35 | B36: 46035 | C36: 1945 | D36: CAÑAVATE FERNANDEZ, CARMINA | E36: 11 | F36: =IFERROR(LOOKUP(E36,CODIGOS!A:A,CODIGOS!B:B)," ") -> OLLA SAN ANTÓN | H36: =IF(J36="SI",IFERROR(LOOKUP(E36,CODIGOS!A:A,CODIGOS!C:C)," "),IFERROR(LOOKUP(E36,CODIGOS!A:A,CODIGOS!D:D),"")) -> 25 | I36: =IFERROR(LOOKUP(C36,SOCIO!A:A,SOCIO!D:D)," ") -> SI | J36: =IFERROR(LOOKUP(D36,SOCIO!B:B,SOCIO!C:C)," ") -> SI
A37: =IF(B37<>0,A36+1," ") -> 36 | B37: 46035 | C37: 1945 | D37: CAÑAVATE FERNANDEZ, CARMINA | E37: 10 | F37: =IFERROR(LOOKUP(E37,CODIGOS!A:A,CODIGOS!B:B)," ") -> ÓRGIVA | H37: =IF(J37="SI",IFERROR(LOOKUP(E37,CODIGOS!A:A,CODIGOS!C:C)," "),IFERROR(LOOKUP(E37,CODIGOS!A:A,CODIGOS!D:D),"")) -> 22 | I37: =IFERROR(LOOKUP(C37,SOCIO!A:A,SOCIO!D:D)," ") -> SI | J37: =IFERROR(LOOKUP(D37,SOCIO!B:B,SOCIO!C:C)," ") -> SI
A38: =IF(B38<>0,A37+1," ") -> 37 | B38: 46035 | C38: 1923 | D38: CONSUEGRA NAVARRO, JOSE MARIA | E38: 11 | F38: =IFERROR(LOOKUP(E38,CODIGOS!A:A,CODIGOS!B:B)," ") -> OLLA SAN ANTÓN | H38: =IF(J38="SI",IFERROR(LOOKUP(E38,CODIGOS!A:A,CODIGOS!C:C)," "),IFERROR(LOOKUP(E38,CODIGOS!A:A,CODIGOS!D:D),"")) -> 25 | I38: =IFERROR(LOOKUP(C38,SOCIO!A:A,SOCIO!D:D)," ") -> SI | J38: =IFERROR(LOOKUP(D38,SOCIO!B:B,SOCIO!C:C)," ") -> SI
A39: =IF(B39<>0,A38+1," ") -> 38 | B39: 46035 | C39: 1923 | D39: CONSUEGRA NAVARRO, JOSE MARIA | E39: 10 | F39: =IFERROR(LOOKUP(E39,CODIGOS!A:A,CODIGOS!B:B)," ") -> ÓRGIVA | H39: =IF(J39="SI",IFERROR(LOOKUP(E39,CODIGOS!A:A,CODIGOS!C:C)," "),IFERROR(LOOKUP(E39,CODIGOS!A:A,CODIGOS!D:D),"")) -> 22 | I39: =IFERROR(LOOKUP(C39,SOCIO!A:A,SOCIO!D:D)," ") -> SI | J39: =IFERROR(LOOKUP(D39,SOCIO!B:B,SOCIO!C:C)," ") -> SI
A40: =IF(B40<>0,A39+1," ") -> 39 | B40: 46035 | C40: 2219 | D40: CANO SANCHEZ, CARMEN | E40: 1 | F40: =IFERROR(LOOKUP(E40,CODIGOS!A:A,CODIGOS!B:B)," ") -> CUOTA SOCIO | H40: =IF(J40="SI",IFERROR(LOOKUP(E40,CODIGOS!A:A,CODIGOS!C:C)," "),IFERROR(LOOKUP(E40,CODIGOS!A:A,CODIGOS!D:D),"")) -> 30 | I40: =IFERROR(LOOKUP(C40,SOCIO!A:A,SOCIO!D:D)," ") -> NO | J40: =IFERROR(LOOKUP(D40,SOCIO!B:B,SOCIO!C:C)," ") -> SI
...

Sheet Hoja1

Sheet SOCIOS
A1: Nº Socio | B1: NOMBRE | C1: DNI | D1: DOMICILIO | E1: COD. POSTAL | F1: MUNICIPIO | G1: TELEFONO | H1: CORREO
A2: 269 | B2: JUAN FRANCISCO ACEÑA CABALLERO | C2: 1121212A | D2: PETRA,32 | E2: 18001 | F2: GRANADA | G2: 658555555 | H2: pepe@dsds
A3: 410 | B3: LUCIA LOPEZ BIEZMA | C3: 1121212A | D3: PETRA,33 | E3: 18002 | F3: GRANADA | G3: 658555556 | H3: pepe@dsds
A4: 575 | B4: TERESA BAUTISTA MENDEZ | C4: 1121212A | D4: PETRA,34 | E4: 18003 | F4: GRANADA | G4: 658555557 | H4: pepe@dsds
A5: 738 | B5: Mª TERESA ROZUA LARIOS | C5: 1121212A | D5: PETRA,35 | E5: 18004 | F5: GRANADA | G5: 658555558 | H5: pepe@dsds
A6: 810 | B6: Dionisio Gonzalez Gonzalez | C6: 1121212A | D6: PETRA,36 | E6: 18005 | F6: GRANADA | G6: 658555559 | H6: pepe@dsds
A7: 849 | B7: Purificación Rodríguez Franco | C7: 1121212A | D7: PETRA,37 | E7: 18006 | F7: GRANADA | G7: 658555560 | H7: pepe@dsds
A8: 1030 | B8: ANTONIO ALCALDE CASTILLA | C8: 1121212A | D8: PETRA,38 | E8: 18007 | F8: GRANADA | G8: 658555561 | H8: pepe@dsds
A9: 1042 | B9: LEONARDO SEGURA HERRERA | C9: 1121212A | D9: PETRA,39 | E9: 18008 | F9: GRANADA | G9: 658555562 | H9: pepe@dsds
A10: 1045 | B10: SANCHEZ ROMERO MARÍA | C10: 1121212A | D10: PETRA,40 | E10: 18009 | F10: GRANADA | G10: 658555563 | H10: pepe@dsds
A11: 1141 | B11: PILAR ESTRELLA MANCILLA GUARDIA | C11: 1121212A | D11: PETRA,41 | E11: 18010 | F11: GRANADA | G11: 658555564 | H11: pepe@dsds
A12: 1178 | B12: Rufo del Castillo Gordo | C12: 1121212A | D12: PETRA,42 | E12: 18011 | F12: GRANADA | G12: 658555565 | H12: pepe@dsds
A13: 1251 | B13: Maria Hortencia Martinez Raya | C13: 1121212A | D13: PETRA,43 | E13: 18012 | F13: GRANADA | G13: 658555566 | H13: pepe@dsds
... A20: 1623 | B20: Mercedes Rios Collantes | C20: 1121212A | D20: PETRA,50 | E20: 18019 | F20: GRANADA | G20: 658555573 | H20: pepe@dsds
A21: 1674 | B21: Antonio Fernández Cabello
A22: 1680 | B22: LOLI CONTRERAS GONZALEZ
A23: 1744 | B23: Mª DEL PILAR DE MAQUA MONTEYS
A24: 1745 | B24: LOLA CANTARERO CABALLERO
A25: 1803 | B25: MARI CARMEN JIMENEZ BARRIONUEVO
A26: 1815 | B26: Mº Concepcion Fdez Montoya
A27: 1823 | B27: INMA CAÑAVATE
A28: 1836 | B28: MARTIN CHIROSA TERESA
A29: 1853 | B29: ENRIQUE ARBOL JIMENEZ
A30: 1856 | B30: DOLORES ROMAN ENRIQUEZ
A31: 1861 | B31: Maria Isabel Martin Aguilar
A32: 1888 | B32: Maria Navarro de la Casa
... A320: 5000 | B320: ACOMPAÑANTE

Sheet SOCIO
A1: NUMERO | B1: SOCIO | C1: ACTIVO | D1: matricula
A2: 2411 | B2: ACEBAL MIÑANO, MARIA DEL MILAGRO | C2: SI | D2: SI
A3: 2303 | B3: ACEBES ORIHUELA, FRANCISCA | C3: SI | D3: SI
A4: 269 | B4: ACEÑA CABALLERO, JUAN FRANCISCO | C4: SI | D4: NO
A5: 3045 | B5: ACOSTA ROBLES, PABLO | C5: SI | D5: SI
A6: 2940 | B6: AGUILAR RAMIREZ, JOSE | C6: SI | D6: SI
A7: 2773 | B7: AGUIRRE GALLEGO, JOSE LUIS | C7: SI | D7: NO
A8: 2377 | B8: ALCALA VILCHEZ, MANUEL | C8: SI | D8: SI
A9: 1030 | B9: ALCALDE CASTILLA, ANTONIO | C9: SI | D9: SI
A10: 2369 | B10: ALGAR REYES , LEONOR | C10: SI | D10: SI
A11: 2505 | B11: ALONSO SAEZ, INMACULADA | C11: SI | D11: SI
A12: 2419 | B12: ALVAREZ DE CIENFUEGOS LOPEZ, CARMEN | C12: SI | D12: SI
A13: 3047 | B13: ALVAREZ MARTINEZ,, YOLANDA | C13: SI | D13: SI
... A196: 3046 | B196: GONZALEZ RODRIGUEZ, MARIA DOLORES | C196: SI | D196: SI
A197: 3112 | B197: GRANERO EXPÓSITO, ESPERANZA | C197: SI
A198: 2817 | B198: GUERRERO BARQUERO, JOSE ANTONIO | C198: SI | D198: SI
A199: 3130 | B199: GUERRERO JIMÉNEZ, AMPARO | C199: SI | D199: SI
A200: 3129 | B200: GUERRERO SOLANO, NIEVES | C200: SI | D200: SI
A201: 2902 | B201: GUILLEN GONZALEZ -NOVO , EDUARDO | C201: SI | D201: SI
A202: 2850 | B202: GUTIERREZ MELENDEZ, VICENTA | C202: SI | D202: SI
A203: 2524 | B203: GUZMAN LIRIO, MARIA ANGUSTIAS | C203: SI | D203: SI
A204: 2885 | B204: HARO ARRABAL, AFRICA | C204: SI | D204: SI
A205: 1920 | B205: HERAS JIMENEZ, JOSE FRANCISCO | C205: SI | D205: SI
A206: 2923 | B206: HERNANDEZ OGAYAR, PAULA | C206: SI | D206: SI
A207: 3139 | B207: HERNANDEZ PRIETO, JUAN | C207: SI | D207: SI
A208: 2584 | B208: HERNANDEZ VALLECILLO, MARIA TERESA | C208: SI | D208: SI
A209: 2614 | B209: HERVIAS GARRIDO, Mª REMEDIOS | C209: SI | D209: SI
... A319: 2881 | B319: MONTERO ORTIZ, MARIA TERESA | C319: SI | D319: SI
A320: 2978 | B320: MONTES GOMEZ, MARIA DEL CAEMEN | C320: SI
A321: 3072 | B321: MONTORE MONTORE, MARIA DEL PILAR | C321: SI | D321: NO
A322: 3002 | B322: MONTOYA RAMÍREZ, ROSALÍA | C322: SI | D322: SI
A323: 2991 | B323: MORA DE SAAVEDRA, ROSARIO | C323: SI | D323: SI
A324: 2983 | B324: MORALES BRAOJOS, MARIA DEL MAR | C324: SI | D324: SI
A325: 3122 | B325: MORALES DUARTE, MARIA DOLORES | C325: SI | D325: SI
A326: 2877 | B326: MORALES GARCÍA, Mª TRINIDAD | C326: SI | D326: SI
A327: 2532 | B327: MORALES GONZALEZ, VALERIANO | C327: SI | D327: SI
A328: 3064 | B328: MORALES PASADAS, CRISTOBAL JOSE | C328: SI | D328: SI
A329: 3103 | B329: MORALLON FUENTES, M. DEL CARMEN | C329: SI | D329: NO
A330: 3071 | B330: MORENO MARTINEZ, ROSA MARÍA | C330: SI | D330: SI
A331: 2516 | B331: MORENO MORENO, JOSE LUIS | C331: SI | D331: SI
...

Sheet RECIBO
D1: RECIBO Nº
D2: 177
D4: º
B5: ALUMA
B6: ASOCIACIÓN DE ALUMNOS DEL AULA
B7: PERMANENTE DE FORMACIÓN ABIERTA
B8: UNIVERSIDAD DE GRANADA
B9: N.I.F. G18429068
B10: Avd. Madrid, 3 Espacio V Centenario
B11: 18070 - GRANADA
B13: =CONCATENATE("RECIBO Nº ",D2) -> RECIBO Nº 177
B15: Hemos recibido de
B16: =IFERROR(LOOKUP(D2,'DIARIO 2026'!A:A,'DIARIO 2026'!D:D)," ") -> MOYANO REDONDO , JULIO
B17: =CONCATENATE("la cantidad de ",LOOKUP(D2,'DIARIO 2026'!A:A,'DIARIO 2026'!H:H)," Euros") -> la cantidad de 20 Euros
B18: en concepto de
B19: =LOOKUP(D2,'DIARIO 2026'!A:A,'DIARIO 2026'!F:F) -> VISITA A FONELAS
B20: =IFERROR(LOOKUP(D2,'DIARIO 2026'!A:A,'DIARIO 2026'!B:B)," ") -> 46070
I235: =+RECIBO!D2232 -> 0

Sheet CODIGOS
A1: COD | B1: CONCEPTO | C1: IMPORTE | D1: NO SOCIO
A2: 1 | B2: CUOTA SOCIO | C2: 30
A3: 2 | B3: CUOTA NUEVO SOCIO | C3: 30
A4: 3
A5: 4 | B5: DEVOLUCION
A6: 5
A7: 6
A8: 7
A9: 8
A10: 9
A11: 10 | B11: ÓRGIVA | C11: 22 | D11: 27
A12: 11 | B12: OLLA SAN ANTÓN | C12: 25 | D12: 30
A13: 12 | B13: EXPOSICIÓN CATEDRAL | C13: 3 | D13: 3
A14: 13 | B14: ENSAYO ORQUESTA | C14: 0 | D14: 0
A15: 14 | B15: BASÍLICA DE SAN JUAN DE DIOS | C15: 5 | D15: 6
A16: 15 | B16: MUSEO SAN JUAN DE DIOS CP | C16: 5 | D16: 6
A17: 16 | B17: LA CARTUJA | C17: 7 | D17: 8
A18: 17 | B18: VISITA CASA DE LOS PISAS | C18: 5 | D18: 5
A19: 18 | B19: COMIDA DE PATRONA | C19: 55
A20: 19 | B20: VISITA MOTRIL | C20: 15
A21: 20 | B21: VISITA A FONELAS | C21: 20 | D21: 25
A22: 21
A23: 22
A24: 23
A25: 24
A26: 25
A27: 26
A28: 27
A29: 28
A30: 29
A31: 30
A32: 31
A33: 32
... A57: 99

Sheet FACTURAS
A1: DATOS FACTURA | J1: PAGO | N1: ACTIVIDAD
A2: ORDEN | B2: FECHA | C2: NÚMERO | D2: ACREEDOR | E2: CONCEPTO | F2: BASE | G2: IVA | H2: IRPF | I2: TOTAL | J2: P | K2: FECHA | L2: IMPORTE | M2: OBSER. | N2: COD. | O2: DENOMINACIÓN
O3: =IFERROR(LOOKUP(N:N,CODIGOS!A:A,CODIGOS!B:B),"")
O4: =IFERROR(LOOKUP(N:N,CODIGOS!A:A,CODIGOS!B:B),"")
O5: =IFERROR(LOOKUP(N:N,CODIGOS!A:A,CODIGOS!B:B),"")
O6: =IFERROR(LOOKUP(N:N,CODIGOS!A:A,CODIGOS!B:B),"")
O7: =IFERROR(LOOKUP(N:N,CODIGOS!A:A,CODIGOS!B:B),"")
O8: =IFERROR(LOOKUP(N:N,CODIGOS!A:A,CODIGOS!B:B),"")
O9: =IFERROR(LOOKUP(N:N,CODIGOS!A:A,CODIGOS!B:B),"")
O10: =IFERROR(LOOKUP(N:N,CODIGOS!A:A,CODIGOS!B:B),"")
O11: =IFERROR(LOOKUP(N:N,CODIGOS!A:A,CODIGOS!B:B),"")
O12: =IFERROR(LOOKUP(N:N,CODIGOS!A:A,CODIGOS!B:B),"")
O13: =IFERROR(LOOKUP(N:N,CODIGOS!A:A,CODIGOS!B:B),"")
O14: =IFERROR(LOOKUP(N:N,CODIGOS!A:A,CODIGOS!B:B),"")
... O238: =IFERROR(LOOKUP(N:N,CODIGOS!A:A,CODIGOS!B:B),"")

Sheet ACREED
